Failure # 1 (occurred at 2024-03-26_12-07-21)
[36mray::ImplicitFunc.train()[39m (pid=96178, ip=127.0.0.1, actor_id=c76e346e0b09df45dd83fc1c01000000, repr=main)
           ^^^^^^^^^^^^^^^^^^^^^^^^^^^^^^^^^^^^
           ^^^^^^^^^^^^^^^^^^^^^^^^^^^^^^^
  File "/Users/nicolasvila/miniconda3/lib/python3.11/site-packages/ray/tune/trainable/trainable.py", line 342, in train
    raise skipped from exception_cause(skipped)
  File "/Users/nicolasvila/miniconda3/lib/python3.11/site-packages/ray/air/_internal/util.py", line 88, in run
    self._ret = self._target(*self._args, **self._kwargs)
                ^^^^^^^^^^^^^^^^^^^^^^^^^^^^^^^^^^^^^^^^^
  File "/Users/nicolasvila/miniconda3/lib/python3.11/site-packages/ray/tune/trainable/function_trainable.py", line 115, in <lambda>
    training_func=lambda: self._trainable_func(self.config),
                          ^^^^^^^^^^^^^^^^^^^^^^^^^^^^^^^^^
           ^^^^^^^^^^^^^^^^^^^^^^^^^^^^^^^
  File "/Users/nicolasvila/miniconda3/lib/python3.11/site-packages/ray/tune/trainable/function_trainable.py", line 332, in _trainable_func
    output = fn()
             ^^^^
  File "/Users/nicolasvila/workplace/uni/tfg_v2/tests/main/qreps/cleanrl/qreps_v3_tune.py", line 178, in main
    args.seed = config["__trial_index__"] + SEED_OFFSET
    ^^^^
UnboundLocalError: cannot access local variable 'args' where it is not associated with a value
